Workbook

Sheet Cover
B3: DMART (AVENUE SUPERMARTS LTD.)
B4: Financial Statement & Ratio Analysis | FY2022 – FY2026
B8: 5-YEAR FUNDAMENTAL & RATIO ANALYSIS | CONSOLIDATED FINANCIALS (FY22–FY26)
B10: Prepared By | D10: Mihir, CMA Intermediate student, ICMAI
B11: Purpose | D11: Independent portfolio exercise applying financial statement analysis, ratio interpretation and working-capital modelling to a live listed company
B12: Company Analysed | D12: Avenue Supermarts Ltd. (NSE: DMART) | Organised Retail / Hypermarket
B13: Period Covered | D13: FY2022–FY2026 (Indian FY: April–March), Consolidated Financials
B14: Data Source | D14: Screener.in and DMART Annual Reports; extracted via a self-written Python (yfinance) script into this workbook
B15: Tools Used | D15: Microsoft Excel (formula-driven model with native charts) and Python (data extraction & automation)
B16: Report Contains | D16: Assumptions & definitions, ratio analysis, Baumol cash model, key observations, and full P&L / Balance Sheet / Cash Flow statements
B18: CONTENTS OF THIS WORKBOOK
B19: Assumption | D19: Standard assumptions, formula definitions and data-source notes for every ratio used
B20: Ratio Analysis | D20: Trend, Profitability, Liquidity, Inventory, Cash Management (Baumol Model), Leverage & Efficiency ratios
B21: Analysis | D21: Key observations and interpretation, with supporting charts
B22: Profit & Loss | D22: 5-year Profit & Loss statement (₹ Crores)
B23: Balance Sheet | D23: 5-year Balance Sheet (₹ Crores)
B24: Cashflow Statement | D24: 5-year Cash Flow Statement (₹ Crores)
B26: Disclaimer: Prepared solely as an academic/portfolio exercise to demonstrate financial statement analysis skills. This is not investment advice or a research report under SEBI (Research Analysts) Regulations. Figures are sourced from publicly available data (Screener.in / Annual Reports) and may contain rounding differences. Market Value Ratios are excluded as live market price data was not used.

Sheet Summary
B3: EXECUTIVE SUMMARY
B4: Avenue Supermarts Ltd. (DMART) — FY2022–FY2026 Financial Statement & Ratio Analysis
B8: ANALYST VERDICT — FY26
B9: DMart remains a financially sound, low-leverage retailer that has more than doubled revenue over FY22–FY26 (₹30,976 Cr to ₹68,821 Cr), but its FY23 peak in capital efficiency has not been repeated. ROCE has declined from 14.3% (FY23) to 11.5% (FY26) and ROE from 14.8% to 12.1%, even as the balance sheet stayed conservative (Debt-to-Equity of just 0.10x). Margins are broadly stable but under mild pressure, EBITDA margin has slipped from 8.5% (FY23) to 7.5% (FY26) — while liquidity, though still comfortable, has thinned considerably (Current Ratio down from 3.7x to 2.0x; Cash Ratio down from 0.96x to 0.08x). The combination of slowing sales growth (38% in FY23 to 16% in FY26), rising capex intensity, and a first-time use of short-term borrowings in FY26 suggests a business self-funding an aggressive store-expansion and quick-commerce response, at some cost to near-term capital efficiency. None of this indicates financial distress — coverage and solvency remain very strong — but the FY23-to-FY26 direction of travel on returns and liquidity is the trend worth monitoring.
B11: FY26 SNAPSHOT (vs. FY22)
B13: Revenue (₹ Cr) | D13: Net Profit (₹ Cr) | F13: ROCE | H13: ROE
B14: ='Profit & Loss'!F4 -> 68821 | D14: ='Profit & Loss'!F21 -> 2970 | F14: ='Ratio Analysis'!F10 -> 0.11540255 | H14: ='Ratio Analysis'!F11 -> 0.12140288
B15: ="FY22: "&TEXT('Profit & Loss'!B4,"#,##0") -> FY22: 30,976 | D15: ="FY22: "&TEXT('Profit & Loss'!B21,"#,##0") -> FY22: 1,492 | F15: ="FY22: "&TEXT('Ratio Analysis'!B10,"0.0%") -> FY22: 10.5% | H15: ="FY22: "&TEXT('Ratio Analysis'!B11,"0.0%") -> FY22: 10.9%
B17: DUPONT ROE DECOMPOSITION (Net Margin × Asset Turnover × Equity Multiplier = ROE)
B18: Component | C18: FY22 | D18: FY23 | E18: FY24 | F18: FY25 | G18: FY26 | H18: NOTES:
B19: Net Profit Margin (Net Profit / Sales) | C19: ='Profit & Loss'!B21/'Profit & Loss'!B4 -> 0.048166322 | D19: ='Profit & Loss'!C21/'Profit & Loss'!C4 -> 0.05550887 | E19: ='Profit & Loss'!D21/'Profit & Loss'!D4 -> 0.049932072 | F19: ='Profit & Loss'!E21/'Profit & Loss'!E4 -> 0.045604636 | G19: ='Profit & Loss'!F21/'Profit & Loss'!F4 -> 0.043155432 | H19: The Company is converting less of its sales into bottom line profit. This indicates intensifying pressure on core operating margine, rising overheads, or higher interest/tax expenses.
B20: Asset Turnover (Sales / Total Assets) | C20: ='Profit & Loss'!B4/'Balance Sheet'!B38 -> 2.0021977 | D20: ='Profit & Loss'!C4/'Balance Sheet'!C38 -> 2.3661972 | E20: ='Profit & Loss'!D4/'Balance Sheet'!D38 -> 2.3988759 | F20: ='Profit & Loss'!E4/'Balance Sheet'!E38 -> 2.4414099 | G20: ='Profit & Loss'!F4/'Balance Sheet'!F38 -> 2.3314926 | H20: The company became highly efficient at sweat-testing its assets to generate revenue up until FY25. The reversal in FY26 implies that either revenue growth slowed down significantly or the company took on underutilized assets that aren't yet generating proportional sales.
B21: Equity Multiplier (Total Assets / Equity) | C21: ='Ratio Analysis'!B44 -> 1.1310864 | D21: ='Ratio Analysis'!C44 -> 1.1260729 | E21: ='Ratio Analysis'!D44 -> 1.1323136 | F21: ='Ratio Analysis'!E44 -> 1.1346369 | G21: ='Ratio Analysis'!F44 -> 1.2065893 | H21: For four years, management kept a conservative debt profile. The spike in FY26 shows the company added significant leverage (taking on more debt relative to equity).
B22: ROE (computed) | C22: =C19*C20*C21 -> 0.10908027 | D22: =D19*D20*D21 -> 0.14790397 | E22: =E19*E20*E21 -> 0.13562948 | F22: =F19*F20*F21 -> 0.12633004 | G22: =G19*G20*G21 -> 0.12140288
B23: Reported ROE (Ratio Analysis tab, cross-check) | C23: ='Ratio Analysis'!B11 -> 0.10908027 | D23: ='Ratio Analysis'!C11 -> 0.14790397 | E23: ='Ratio Analysis'!D11 -> 0.13562948 | F23: ='Ratio Analysis'!E11 -> 0.12633004 | G23: ='Ratio Analysis'!F11 -> 0.12140288
B25: STRENGTHS | F25: AREAS TO WATCH
B26: ✓ Very low leverage: Debt-to-Equity just 0.10x in FY26; Interest Coverage 29.7x | F26: ! ROCE and ROE both declined from their FY23 peak (14.3%→11.5% and 14.8%→12.1%)
B27: ✓ Revenue more than doubled over FY22–FY26 (₹30,976 Cr → ₹68,821 Cr) | F27: ! Current Ratio nearly halved (3.7x→2.0x) and Cash Ratio fell sharply (0.96x→0.08x)
B28: ✓ Gross margin stable at ~15% throughout the period — pricing/sourcing discipline intact | F28: ! First-time short-term borrowings (₹965 Cr) appear in FY26 — new for this balance sheet
B29: ✓ Strong free-cash-generating core operations; investing cash use is capex-led, not distress-led | F29: ! Inventory Days rising (28→32) alongside quick-commerce user growth — worth monitoring
B31: METHODOLOGY & DATA PIPELINE
B32: Data extraction | D32: A self-written Python script (main.py) pulls DMart's historical financial statements via the yfinance API and writes them into a structured Excel output — automating what would otherwise be manual copy-paste from Screener.in / annual reports.
B33: Model construction | D33: All ratios in this workbook are formula-driven (not hardcoded), linked live to the Profit & Loss, Balance Sheet, and Cash Flow tabs, so the model recalculates automatically if source figures are updated.
B34: Analytical layers applied | D34: Trend analysis, DuPont ROE decomposition, liquidity/leverage/efficiency ratios, Baumol optimal cash balance model, and operating/financial/combined leverage (DOL/DFL/DCL).
B35: Repository structure | D35: main.py (data extraction) and this workbook (analysis layer) form one pipeline: raw data in, audited financial model out.
B37: Limitations: Market Value Ratios (P/E, P/B, EV/EBITDA) are excluded as live market price data was not incorporated. This is a financial statement and ratio analysis, not a valuation or investment recommendation.

Sheet Assumption
A1: Standard Assumptions
A2: BASE YEAR FOR TREND ANALYSIS | B2: 44621
A3: Gross Profit | B3: ="Sales - Direct expenses" -> Sales - Direct expenses
A4: Capital Employed | B4: 44621 | C4: 44986 | D4: 45352 | E4: 45717 | F4: 46082
B5: ='Balance Sheet'!B38-'Balance Sheet'!B15 -> 14253 | C5: ='Balance Sheet'!C38-'Balance Sheet'!C15 -> 16638 | D5: ='Balance Sheet'!D38-'Balance Sheet'!D15 -> 19193 | E5: ='Balance Sheet'!E38-'Balance Sheet'!E15 -> 22101 | F5: ='Balance Sheet'!F38-'Balance Sheet'!F15 -> 25736
A6: O (Transaction Cost per Conversion) | B6: Since the company's actual treasury transaction cost is not publicly disclosed, ₹500 per conversion has been assumed as a standard transaction cost for the purpose of applying the Baumol Cash Management Model. This assumption is consistent with the ₹500 per conversion used in an ICMAI Financial Management worked example.
A7: C (Opportunity Cost of Cash) | B7: The opportunity cost of cash is assumed based on the RBI-published Weighted Average Domestic Term Deposit Rate (WADTDR) for fresh rupee term deposits, used as a proxy for the return that could have been earned by investing idle cash in bank fixed/term deposits.
A9: Additional Assumptions
A10: Data Source | B10: Screener.in / DMART Annual Reports (Consolidated Financials, FY22-FY26)
A11: Currency & Units | B11: All figures in ₹ Crores unless stated otherwise
A12: Financial Year Convention | B12: FY22 = Year ended March 2022, and so on (Indian FY: April-March)
A13: Gross Profit Margin % | B13: Gross Profit / Sales
A14: EBITDA Margin % | B14: Operating Profit (EBITDA) / Sales
A15: Net Profit Margin % | B15: Net Profit / Sales
A16: ROCE | B16: Net Profit / Capital Employed (Capital Employed = Total Assets - Total Current Liabilities)
A17: ROE | B17: Net Profit / Shareholders' Equity (Equity Capital + Reserves)
A18: Current Ratio | B18: Total Current Assets / Total Current Liabilities
A19: Quick Ratio | B19: (Total Assets - Inventories) / Total Current Liabilities
A20: Cash Ratio | B20: Cash Equivalents / Total Current Liabilities
A21: Inventory Turnover Ratio | B21: Expenses (COGS proxy) / Average Inventory
... A27: Base Year Treatment | B27: FY22 is the base year for YoY trend analysis; growth % is left blank as no prior year exists
A29: Leverage & Solvency, Efficiency, and Leverage Analysis Definitions
A30: Debt-to-Equity Ratio | B30: Total Borrowings / Shareholders' Equity (Equity Capital + Reserves)
A31: Debt-to-Assets Ratio | B31: Total Borrowings / Total Assets
A32: Equity Multiplier | B32: Total Assets / Shareholders' Equity
A33: Interest Coverage Ratio | B33: EBIT / Interest Expense (EBIT = Profit Before Tax + Interest)
A34: Total Liabilities to Equity | B34: Total Liabilities / Shareholders' Equity
A35: Working Capital Turnover | B35: Sales / Net Working Capital (Total Current Assets - Total Current Liabilities)
A36: Fixed Asset Turnover | B36: Sales / Net Fixed Assets
A37: Receivable Days | B37: 365 / Receivables Turnover
A38: Cash Conversion Cycle | B38: Inventory Days + Receivable Days - Payable Days
A39: EBIT | B39: Profit Before Tax + Interest (used as the EBIT proxy throughout, since this P&L layout does not report EBIT directly)
A40: DOL (Degree of Operating Leverage) | B40: % change in EBIT / % change in Sales (YoY basis; blank for FY22 base year as no prior year exists). Calculated off P&L trend data since a fixed-cost/variable-cost split is not disclosed.
A41: DFL (Degree of Financial Leverage) | B41: EBIT / Profit Before Tax (equivalent to EBIT / (EBIT - Interest))
... A45: Market Value Ratios | B45: Not calculated - requires DMART's market share price and shares outstanding, which are not part of this workbook's data

Sheet Ratio Analysis
A1: Trend Analysis
A2: YoY Trend Analysis | B2: 44621 | C2: 44986 | D2: 45352 | E2: 45717 | F2: 46082
A3: Sales Growth % | B3: N/A | C3: =('Profit & Loss'!C4-'Profit & Loss'!B4)/'Profit & Loss'!B4 -> 0.3830062 | D3: =('Profit & Loss'!D4-'Profit & Loss'!C4)/'Profit & Loss'!C4 -> 0.18555089 | E3: =('Profit & Loss'!E4-'Profit & Loss'!D4)/'Profit & Loss'!D4 -> 0.16871764 | F3: =('Profit & Loss'!F4-'Profit & Loss'!E4)/'Profit & Loss'!E4 -> 0.15942249
A4: Gross Profit Margin % | B4: ='Profit & Loss'!B9/'Profit & Loss'!B4 -> 0.14779184 | C4: ='Profit & Loss'!C9/'Profit & Loss'!C4 -> 0.15070028 | D4: ='Profit & Loss'!D9/'Profit & Loss'!D4 -> 0.14796511 | E4: ='Profit & Loss'!E9/'Profit & Loss'!E4 -> 0.14835406 | F4: ='Profit & Loss'!F9/'Profit & Loss'!F4 -> 0.15054998
A5: EBITDA Margin % | B5: ='Profit & Loss'!B13/'Profit & Loss'!B4 -> 0.080772211 | C5: ='Profit & Loss'!C13/'Profit & Loss'!C4 -> 0.084943978 | D5: ='Profit & Loss'!D13/'Profit & Loss'!D4 -> 0.080844277 | E5: ='Profit & Loss'!E13/'Profit & Loss'!E4 -> 0.075726945 | F5: ='Profit & Loss'!F13/'Profit & Loss'!F4 -> 0.075398498
A8: Profitability Ratio
A9: Profitability Ratio: | B9: Mar-22 | C9: Mar-23 | D9: Mar-24 | E9: Mar-25 | F9: Mar-26
A10: ROCE | B10: ='Profit & Loss'!B21/Assumption!B5 -> 0.10467972 | C10: ='Profit & Loss'!C21/Assumption!C5 -> 0.14292583 | D10: ='Profit & Loss'!D21/Assumption!D5 -> 0.13213151 | E10: ='Profit & Loss'!E21/Assumption!E5 -> 0.12248315 | F10: ='Profit & Loss'!F21/Assumption!F5 -> 0.11540255
A11: ROE | B11: ='Profit & Loss'!B21/('Balance Sheet'!B4+'Balance Sheet'!B5) -> 0.10908027 | C11: ='Profit & Loss'!C21/('Balance Sheet'!C4+'Balance Sheet'!C5) -> 0.14790397 | D11: ='Profit & Loss'!D21/('Balance Sheet'!D4+'Balance Sheet'!D5) -> 0.13562948 | E11: ='Profit & Loss'!E21/('Balance Sheet'!E4+'Balance Sheet'!E5) -> 0.12633004 | F11: ='Profit & Loss'!F21/('Balance Sheet'!F4+'Balance Sheet'!F5) -> 0.12140288
A12: Net Profit Margin % | B12: ='Profit & Loss'!B21/'Profit & Loss'!B4 -> 0.048166322 | C12: ='Profit & Loss'!C21/'Profit & Loss'!C4 -> 0.05550887 | D12: ='Profit & Loss'!D21/'Profit & Loss'!D4 -> 0.049932072 | E12: ='Profit & Loss'!E21/'Profit & Loss'!E4 -> 0.045604636 | F12: ='Profit & Loss'!F21/'Profit & Loss'!F4 -> 0.043155432
A15: Liquidity Ratio
A16: Liquidity Ratio: | B16: 44621 | C16: 44986 | D16: 45352 | E16: 45717 | F16: 46082
A17: Current Ratio | B17: ='Balance Sheet'!B37/'Balance Sheet'!B15 -> 2.8267652 | C17: ='Balance Sheet'!C37/'Balance Sheet'!C15 -> 3.7137014 | D17: ='Balance Sheet'!D37/'Balance Sheet'!D15 -> 3.133906 | E17: ='Balance Sheet'!E37/'Balance Sheet'!E15 -> 2.8896926 | F17: ='Balance Sheet'!F37/'Balance Sheet'!F15 -> 1.9772607
A18: Quick Ratio | B18: =('Balance Sheet'!B38-'Balance Sheet'!B31)/'Balance Sheet'!B15 -> 8.5344828 | C18: =('Balance Sheet'!C38-'Balance Sheet'!C31)/'Balance Sheet'!C15 -> 8.4335378 | D18: =('Balance Sheet'!D38-'Balance Sheet'!D31)/'Balance Sheet'!D15 -> 7.3046993 | E18: =('Balance Sheet'!E38-'Balance Sheet'!E31)/'Balance Sheet'!E15 -> 7.8250452 | F18: =('Balance Sheet'!F38-'Balance Sheet'!F31)/'Balance Sheet'!F15 -> 5.6570598
A19: Cash Ratio | B19: ='Balance Sheet'!B34 / 'Balance Sheet'!B15 -> 0.2454844 | C19: ='Balance Sheet'!C34 / 'Balance Sheet'!C15 -> 0.95978187 | D19: ='Balance Sheet'!D34 / 'Balance Sheet'!D15 -> 0.32238504 | E19: ='Balance Sheet'!E34 / 'Balance Sheet'!E15 -> 0.16184448 | F19: ='Balance Sheet'!F34 / 'Balance Sheet'!F15 -> 0.080380751
A21: Inventory Turnover
A22: Inventory Turnover: | B22: Mar-22 | C22: Mar-23 | D22: Mar-24 | E22: Mar-25 | F22: Mar-26
A23: Inventory Turnover Ratio | B23: N/A | C23: ='Profit & Loss'!C5/AVERAGE('Balance Sheet'!B32,'Balance Sheet'!C32) -> 13.097561 | D23: ='Profit & Loss'!D5/AVERAGE('Balance Sheet'!C32,'Balance Sheet'!D32) -> 13.021757 | E23: ='Profit & Loss'!E5/AVERAGE('Balance Sheet'!D32,'Balance Sheet'!E32) -> 12.231412 | F23: ='Profit & Loss'!F5/AVERAGE('Balance Sheet'!E32,'Balance Sheet'!F32) -> 11.627593
A24: Inventory Days | B24: N/A | C24: =ROUNDUP((365/C23),0) -> 28 | D24: =ROUNDUP((365/D23),0) -> 29 | E24: =ROUNDUP((365/E23),0) -> 30 | F24: =ROUNDUP((365/F23),0) -> 32
A25: Receivables Turnover | B25: N/A | C25: ='Profit & Loss'!C4/AVERAGE('Balance Sheet'!B33,'Balance Sheet'!C33) -> 664.18605 | D25: ='Profit & Loss'!D4/AVERAGE('Balance Sheet'!C33,'Balance Sheet'!D33) -> 445.51754 | E25: ='Profit & Loss'!E4/AVERAGE('Balance Sheet'!D33,'Balance Sheet'!E33) -> 370.9875 | F25: ='Profit & Loss'!F4/AVERAGE('Balance Sheet'!E33,'Balance Sheet'!F33) -> 454.26403
A26: Payables Turnover | B26: N/A | C26: ='Profit & Loss'!C5/AVERAGE('Balance Sheet'!B13:C13) -> 58.378258 | D26: ='Profit & Loss'!D5/AVERAGE('Balance Sheet'!C13:D13) -> 53.689477 | E26: ='Profit & Loss'!E5/AVERAGE('Balance Sheet'!D13:E13) -> 53.36965 | F26: ='Profit & Loss'!F5/AVERAGE('Balance Sheet'!E13:F13) -> 52.82856
A27: Payable Days | B27: N/A | C27: =ROUNDUP((365/C26),0) -> 7 | D27: =ROUNDUP((365/D26),0) -> 7 | E27: =ROUNDUP((365/E26),0) -> 7 | F27: =ROUNDUP((365/F26),0) -> 7
A28: Asset Turnover | B28: N/A | C28: ='Profit & Loss'!C4/AVERAGE('Balance Sheet'!B38,'Balance Sheet'!C38) -> 2.5518227 | D28: ='Profit & Loss'!D4/AVERAGE('Balance Sheet'!C38,'Balance Sheet'!D38) -> 2.5861955 | E28: ='Profit & Loss'!E4/AVERAGE('Balance Sheet'!D38,'Balance Sheet'!E38) -> 2.6100033 | F28: ='Profit & Loss'!F4/AVERAGE('Balance Sheet'!E38,'Balance Sheet'!F38) -> 2.5569282
A31: Cash Management Analysis – Baumol Model
A32: Cash Management: | B32: 44621 | C32: 44986 | D32: 45352 | E32: 45717 | F32: 46082
A33: Annual Cash Requirement (A) | B33: ='Cashflow Statement'!B38 -> 3990 | C33: ='Cashflow Statement'!C38 -> 3835 | D33: ='Cashflow Statement'!D38 -> 8902 | E33: ='Cashflow Statement'!E38 -> 10800 | F33: ='Cashflow Statement'!F38 -> 10749
A34: Transaction Cost per Conversion (O) | B34: =500 -> 500 | C34: =500 -> 500 | D34: =500 -> 500 | E34: =500 -> 500 | F34: =500 -> 500
A35: Opportunity Cost of Cash (C) | B35: 0.0412 | C35: 0.0648 | D35: 0.0662 | E35: 0.0665 | F35: 0.0607
A36: Optimal Cash Balance | B36: =SQRT((2*B33*(B34/10000000))/B35) -> 3.1119875 | C36: =SQRT((2*C33*(C34/10000000))/C35) -> 2.4327371 | D36: =SQRT((2*D33*(D34/10000000))/D35) -> 3.6670328 | E36: =SQRT((2*E33*(E34/10000000))/E35) -> 4.029963 | F36: =SQRT((2*F33*(F34/10000000))/F35) -> 4.2081352
A37: Cash Conversion Frequency | B37: =B33/B36 -> 1282.1388 | C37: =C33/C36 -> 1576.4137 | D37: =D33/D36 -> 2427.5757 | E37: =E33/E36 -> 2679.9254 | F37: =F33/F36 -> 2554.3381
A38: Average Cash Balance | B38: =B36/2 -> 1.5559937 | C38: =C36/2 -> 1.2163686 | D38: =D36/2 -> 1.8335164 | E38: =E36/2 -> 2.0149815 | F38: =F36/2 -> 2.1040676
A40: Leverage & Solvency Ratios
A41: Leverage & Solvency: | B41: 44621 | C41: 44986 | D41: 45352 | E41: 45717 | F41: 46082
A42: Debt-to-Equity Ratio | B42: ='Balance Sheet'!B6/('Balance Sheet'!B4+'Balance Sheet'!B5) -> 0.047302237 | C42: ='Balance Sheet'!C6/('Balance Sheet'!C4+'Balance Sheet'!C5) -> 0.039992536 | D42: ='Balance Sheet'!D6/('Balance Sheet'!D4+'Balance Sheet'!D5) -> 0.03166114 | E42: ='Balance Sheet'!E6/('Balance Sheet'!E4+'Balance Sheet'!E5) -> 0.038267687 | F42: ='Balance Sheet'!F6/('Balance Sheet'!F4+'Balance Sheet'!F5) -> 0.099125245
A43: Debt-to-Assets Ratio | B43: ='Balance Sheet'!B6/'Balance Sheet'!B38 -> 0.04182018 | C43: ='Balance Sheet'!C6/'Balance Sheet'!C38 -> 0.035515051 | D43: ='Balance Sheet'!D6/'Balance Sheet'!D38 -> 0.027961459 | E43: ='Balance Sheet'!E6/'Balance Sheet'!E38 -> 0.033726813 | F43: ='Balance Sheet'!F6/'Balance Sheet'!F38 -> 0.082153262
A44: Equity Multiplier | B44: ='Balance Sheet'!B38/('Balance Sheet'!B4+'Balance Sheet'!B5) -> 1.1310864 | C44: ='Balance Sheet'!C38/('Balance Sheet'!C4+'Balance Sheet'!C5) -> 1.1260729 | D44: ='Balance Sheet'!D38/('Balance Sheet'!D4+'Balance Sheet'!D5) -> 1.1323136 | E44: ='Balance Sheet'!E38/('Balance Sheet'!E4+'Balance Sheet'!E5) -> 1.1346369 | F44: ='Balance Sheet'!F38/('Balance Sheet'!F4+'Balance Sheet'!F5) -> 1.2065893
A45: Interest Coverage Ratio | B45: =('Profit & Loss'!B19+'Profit & Loss'!B17)/'Profit & Loss'!B17 -> 39.222222 | C45: =('Profit & Loss'!C19+'Profit & Loss'!C17)/'Profit & Loss'!C17 -> 46.671642 | D45: =('Profit & Loss'!D19+'Profit & Loss'!D17)/'Profit & Loss'!D17 -> 60.672414 | E45: =('Profit & Loss'!E19+'Profit & Loss'!E17)/'Profit & Loss'!E17 -> 54.231884 | F45: =('Profit & Loss'!F19+'Profit & Loss'!F17)/'Profit & Loss'!F17 -> 29.746479
A46: Total Liabilities to Equity | B46: ='Balance Sheet'!B16/('Balance Sheet'!B4+'Balance Sheet'!B5) -> 1.1310864 | C46: ='Balance Sheet'!C16/('Balance Sheet'!C4+'Balance Sheet'!C5) -> 1.1260729 | D46: ='Balance Sheet'!D16/('Balance Sheet'!D4+'Balance Sheet'!D5) -> 1.1323136 | E46: ='Balance Sheet'!E16/('Balance Sheet'!E4+'Balance Sheet'!E5) -> 1.1346369 | F46: ='Balance Sheet'!F16/('Balance Sheet'!F4+'Balance Sheet'!F5) -> 1.2065893
A48: Efficiency Ratios
A49: Efficiency Ratio: | B49: 44621 | C49: 44986 | D49: 45352 | E49: 45717 | F49: 46082
...

Sheet Analysis
A1: Key Observations
A2: 1. Sales growth remained positive but slowed from 38% in Mar-23 to 16% in Mar-26. Over the same period, unique annual transacting users on quick-commerce platforms increased substantially. This suggests growing consumer adoption of quick commerce, although the data alone does not prove that customers are shifting directly from DMart.
A4: Year | B4: Unique Annual Transacting Users (Crores)
A5: 2022 | B5: =AVERAGE(0.8,1) -> 0.9
A6: 2023 | B6: =AVERAGE(1.4,1.7) -> 1.55
A7: 2024 | B7: =AVERAGE(2.4,2.6) -> 2.5
A8: 2025 | B8: =AVERAGE(3.2,3.6) -> 3.4
A9: 2026 | B9: =AVERAGE(4,4.5) -> 4.25
A11: Note: This data shows the number of unique annual transacting users active on quick-commerce platforms, including Blinkit, Zepto, Swiggy Instamart, and Amazon Fresh.
A13: 2. Return on Capital Employed (ROCE) increased from 10% in Mar-22 to 14% in Mar-23, then declined to 12% by Mar-26. This indicates that capital efficiency has weakened from its Mar-23 peak, although ROCE remains above the Mar-22 level.
A29: 3. In Mar-26, the company incurred ₹92.46 of expenses for every ₹100 of sales. As revenue more than doubled from approximately ₹30,976 crore in Mar-22 to ₹68,821 crore in Mar-26, operating expenses increased at a broadly similar rate, leaving the expense-to-sales ratio largely unchanged.
E32: Mar-22 | F32: Mar-23 | G32: Mar-24 | H32: Mar-25 | I32: Mar-26
D33: Expenses per ₹100 of Sales | E33: =('Profit & Loss'!B5/'Profit & Loss'!B4)*100 -> 91.922779 | F33: =('Profit & Loss'!C5/'Profit & Loss'!C4)*100 -> 91.505602 | G33: =('Profit & Loss'!D5/'Profit & Loss'!D4)*100 -> 91.915572 | H33: =('Profit & Loss'!E5/'Profit & Loss'!E4)*100 -> 92.42899 | I33: =('Profit & Loss'!F5/'Profit & Loss'!F4)*100 -> 92.46015
A48: 4. Trade payables increased to ₹1,338 crore by Mar-26, while inventory rose to ₹5,901 crore. The simultaneous increase is consistent with higher working-capital requirements associated with business expansion; however, the available data does not establish the specific operational cause.
A49: 5. Cash outflow from investing activities increased from ₹2,185 crore in Mar-25 to ₹4,207 crore in Mar-26, an increase of approximately 92.5%. The increase was primarily associated with higher purchases of fixed assets.
A50: 6. The inventory turnover ratio declined from 13.1x in Mar-23 to 11.6x in Mar-26, while inventory days increased from 28 to 32 days. This indicates slower inventory movement over the period; however, the available data does not establish quick commerce as the cause.

Sheet Profit & Loss
A1: Profit & Loss Statement
A2: Figures are Represented (₹ in Crores)
B3: 44621 | C3: 44986 | D3: 45352 | E3: 45717 | F3: 46082
A4: Sales - | B4: 30976 | C4: 42840 | D4: 50789 | E4: 59358 | F4: 68821
A5: Expenses - | B5: 28474 | C5: 39201 | D5: 46683 | E5: 54864 | F5: 63632
A6: Material Cost % - | B6: 0.85 | C6: 0.85 | D6: 0.85 | E6: 0.85 | F6: 0.85
A7: Raw material cost | B7: 26892 | C7: 36885 | D7: 43958 | E7: 51669 | F7: 59316
A8: Change in inventory | B8: -494 | C8: -501 | D8: -684 | E8: -1117 | F8: -856
A9: Gross Profit | B9: 4578 | C9: 6456 | D9: 7515 | E9: 8806 | F9: 10361
A10: Manufacturing Cost % | B10: 0.03 | C10: 0.03 | D10: 0.03 | E10: 0.04 | F10: 0.04
A11: Employee Cost % | B11: 0.02 | C11: 0.02 | D11: 0.02 | E11: 0.02 | F11: 0.02
A12: Other Cost % | B12: 0.01 | C12: 0.01 | D12: 0.02 | E12: 0.02 | F12: 0.02
A13: Operating Profit (EBITDA) | B13: 2502 | C13: 3639 | D13: 4106 | E13: 4495 | F13: 5189
A14: Other Income - | B14: 114 | C14: 128 | D14: 145 | E14: 117 | F14: 72
A15: Exceptional items | B15: 0 | C15: 7 | D15: 25 | E15: 15 | F15: 2
... A25: Profit for EPS | B25: 1493 | C25: 2379 | D25: 2536 | E25: 2708 | F25: 2970

Sheet Balance Sheet
A1: Balance Sheet
A2: Figures are Represented (₹ in Crores)
B3: 44621 | C3: 44986 | D3: 45352 | E3: 45717 | F3: 46082
A4: Equity Capital | B4: 648 | C4: 648 | D4: 651 | E4: 651 | F4: 652
A5: Reserves | B5: 13030 | C5: 15430 | D5: 18047 | E5: 20777 | F5: 23812
A6: Borrowings - | B6: 647 | C6: 643 | D6: 592 | E6: 820 | F6: 2425
A7: Long term Borrowings | B7: 0 | C7: 0 | D7: 0 | E7: 0 | F7: 0
A8: Short term Borrowings | B8: 0 | C8: 0 | D8: 0 | E8: 0 | F8: 965
A9: Lease Liabilities | B9: 647 | C9: 643 | D9: 592 | E9: 820 | F9: 1460
A10: Other Borrowings | B10: 0 | C10: 0 | D10: 0 | E10: 0 | F10: 0
A11: Other Liabilities - | B11: 1146 | C11: 1383 | D11: 1882 | E11: 2065 | F11: 2629
A12: Non controlling int | B12: 0 | C12: 0 | D12: 0 | E12: -1 | F12: -2
A13: Trade Payables | B13: 589 | C13: 754 | D13: 985 | E13: 1071 | F13: 1338
A14: Other liability items | B14: 557 | C14: 629 | D14: 898 | E14: 996 | F14: 1292
A15: Total Current Liabilities | B15: 1218 | C15: 1467 | D15: 1979 | E15: 2212 | F15: 3782
... A38: Total Assets | B38: 15471 | C38: 18105 | D38: 21172 | E38: 24313 | F38: 29518

Sheet Cashflow Statement
A1: Cashflow Statements
A2: Figures are Represented (₹ in Crores)
B3: 44621 | C3: 44986 | D3: 45352 | E3: 45717 | F3: 46082
A4: Cash from Operating Activity - | B4: 1372 | C4: 2630 | D4: 2746 | E4: 2463 | F4: 3467
A5: Profit from operations | B5: 2515 | C5: 3659 | D5: 4131 | E5: 4535 | F5: 5233
A6: Receivables | B6: -23 | C6: 5 | D6: -104 | E6: 13 | F6: 4
A7: Inventory | B7: -494 | C7: -501 | D7: -684 | E7: -1117 | F7: -856
A8: Payables | B8: 11 | C8: 165 | D8: 231 | E8: 86 | F8: 267
A9: Loans Advances | B9: 0 | C9: 0 | D9: 0 | E9: 0 | F9: 0
A10: Operating investments | B10: -3 | C10: 0 | D10: 0 | E10: 0 | F10: 0
A11: Other WC items | B11: -73 | C11: 12 | D11: -87 | E11: -94 | F11: -114
A12: Working capital changes | B12: -582 | C12: -320 | D12: -644 | E12: -1113 | F12: -699
A13: Direct taxes | B13: -560 | C13: -709 | D13: -742 | E13: -959 | F13: -1068
A14: Cash from Investing Activity - | B14: -1289 | C14: -2313 | D14: -2468 | E14: -2185 | F14: -4207
A15: Fixed assets purchased | B15: -2410 | C15: -2212 | D15: -2731 | E15: -3423 | F15: -4113
... A37: Free Cash Flow | B37: -1017 | C37: 424 | D37: 24 | E37: -954 | F37: -646
A38: ANNUAL CASH REQUIREMENTS | B38: =-SUMIF(B6:B11,"<0",B6:B11)-MIN(B13,0)-SUMIF(B15:B24,"<0",B15:B24)-SUMIF(B26:B35,"<0",B26:B35) -> 3990 | C38: =-SUMIF(C6:C11,"<0",C6:C11)-MIN(C13,0)-SUMIF(C15:C24,"<0",C15:C24)-SUMIF(C26:C35,"<0",C26:C35) -> 3835 | D38: =-SUMIF(D6:D11,"<0",D6:D11)-MIN(D13,0)-SUMIF(D15:D24,"<0",D15:D24)-SUMIF(D26:D35,"<0",D26:D35) -> 8902 | E38: =-SUMIF(E6:E11,"<0",E6:E11)-MIN(E13,0)-SUMIF(E15:E24,"<0",E15:E24)-SUMIF(E26:E35,"<0",E26:E35) -> 10800 | F38: =-SUMIF(F6:F11,"<0",F6:F11)-MIN(F13,0)-SUMIF(F15:F24,"<0",F15:F24)-SUMIF(F26:F35,"<0",F26:F35) -> 10749
